Workbook

Sheet 0 Index
A1: Master of Starbour — Design Blueprint (structured v2.2)
A2: v2.2 · 2026-10-25 · your blueprint + chat facts (A1–A20) + your answers to Q-01…Q-37 (tab 16). Yellow = yours to fill or a calculator input. Purple 'Proposed' = Claude's placeholder awaiting your yes.
A4: Project
A5: Game | C5: Master of Starbour — 'Starbour' is a pun on harbour / starship; the title is won with the ultimate secret item | K5: Chat A1 · Ans Q-26
A6: Repository | C6: git@github.com:selphaware/master-of-starbour.git — public; code + installable; git over SSH | K6: Chat A2–A3, A7
A7: Local root | C7: E:\CODE\master-of-starbour | K7: Chat A6
A8: Python | C8: 3.12 — venv MOS → E:\CODE\master-of-starbour\MOS\Scripts\python.exe | K8: Chat A5
A9: Target | C9: Downloadable Windows 10/11 executable (PyInstaller one-folder zip, GitHub Releases) | K9: Chat A3 · Ans Q-28
A10: Win | C10: Obtain the ultimate secret item → Master of Starbour: ceremony, then play carries on | K10: Chat A4 · Ans Q-15
A11: Lose | C11: Only when the player's active ship is destroyed; start again with a new seed. Running out of food or water is not game over — the crew mutiny and the captain is demoted to a low-class ship | K11: Chat A6, A10, A11
A12: Style | C12: Colourful throughout; four terminals + engine + launcher over ZeroMQ | K12: Chat A8 · Ans Q-18, Q-25
A14: Tabs & progress
A15: Live counts from each tab's Status column. Proposed = Claude's proposal awaiting your yes — say 'agreed' or change it. 'Open · no Q' = open rows citing no question (plain fill-ins only).
A16: Tab | B16: Group | C16: What it holds | D16: Agreed | E16: Proposed | F16: Draft | G16: Needs detail | H16: Not started | I16: Rows | J16: % Agreed | K16: Open · no Q
A17: =HYPERLINK("#'1 Overview'!A1","1 Overview") -> 1 Overview | B17: Concept | C17: Game type, purpose, player goals, win/lose, turn phases | D17: =COUNTIF('1 Overview'!$F$7:$F$24,"Agreed")+COUNTIF('1 Overview'!$F$29:$F$37,"Agreed") -> 16 | E17: =COUNTIF('1 Overview'!$F$7:$F$24,"Proposed")+COUNTIF('1 Overview'!$F$29:$F$37,"Proposed") -> 4 | F17: =COUNTIF('1 Overview'!$F$7:$F$24,"Draft")+COUNTIF('1 Overview'!$F$29:$F$37,"Draft") -> 4 | G17: =COUNTIF('1 Overview'!$F$7:$F$24,"Needs detail")+COUNTIF('1 Overview'!$F$29:$F$37,"Needs detail") -> 0 | H17: =COUNTIF('1 Overview'!$F$7:$F$24,"Not started")+COUNTIF('1 Overview'!$F$29:$F$37,"Not started") -> 0 | I17: =SUM(D17:H17) -> 24 | J17: =IF(I17=0,0,D17/I17) -> 0.66666667 | K17: =COUNTIFS('1 Overview'!$F$7:$F$24,"Needs detail",'1 Overview'!$D$7:$D$24,"")+COUNTIFS('1 Overview'!$F$7:$F$24,"Not started",'1 Overview'!$D$7:$D$24,"")+COUNTIFS('1 Overview'!$F$29:$F$37,"Needs detail",'1 Overview'!$D$29:$D$37,"")+COUNTIFS('1 Overview'!$F$29:$F$37,"Not started",'1 Overview'!$D$29:$D$37,"") -> 0
A18: =HYPERLINK("#'2 Architecture'!A1","2 Architecture") -> 2 Architecture | B18: Concept | C18: Terminals, bus, process model, message catalogue, diagram | D18: =COUNTIF('2 Architecture'!$G$7:$G$12,"Agreed")+COUNTIF('2 Architecture'!$G$16:$G$23,"Agreed")+COUNTIF('2 Architecture'!$G$28:$G$38,"Agreed") -> 12 | E18: =COUNTIF('2 Architecture'!$G$7:$G$12,"Proposed")+COUNTIF('2 Architecture'!$G$16:$G$23,"Proposed")+COUNTIF('2 Architecture'!$G$28:$G$38,"Proposed") -> 10 | F18: =COUNTIF('2 Architecture'!$G$7:$G$12,"Draft")+COUNTIF('2 Architecture'!$G$16:$G$23,"Draft")+COUNTIF('2 Architecture'!$G$28:$G$38,"Draft") -> 0 | G18: =COUNTIF('2 Architecture'!$G$7:$G$12,"Needs detail")+COUNTIF('2 Architecture'!$G$16:$G$23,"Needs detail")+COUNTIF('2 Architecture'!$G$28:$G$38,"Needs detail") -> 0 | H18: =COUNTIF('2 Architecture'!$G$7:$G$12,"Not started")+COUNTIF('2 Architecture'!$G$16:$G$23,"Not started")+COUNTIF('2 Architecture'!$G$28:$G$38,"Not started") -> 0 | I18: =SUM(D18:H18) -> 22 | J18: =IF(I18=0,0,D18/I18) -> 0.54545455 | K18: =COUNTIFS('2 Architecture'!$G$7:$G$12,"Needs detail",'2 Architecture'!$E$7:$E$12,"")+COUNTIFS('2 Architecture'!$G$7:$G$12,"Not started",'2 Architecture'!$E$7:$E$12,"")+COUNTIFS('2 Architecture'!$G$16:$G$23,"Needs detail",'2 Architecture'!$E$16:$E$23,"")+COUNTIFS('2 Architecture'!$G$16:$G$23,"Not started",'2 Architecture'!$E$16:$E$23,"")+COUNTIFS('2 Architecture'!$G$28:$G$38,"Needs detail",'2 Architecture'!$E$28:$E$38,"")+COUNTIFS('2 Architecture'!$G$28:$G$38,"Not started",'2 Architecture'!$E$28:$E$38,"") -> 0
A19: =HYPERLINK("#'3 T1 Command'!A1","3 T1 Command") -> 3 T1 Command | B19: Terminals | C19: Command catalogue, prompt behaviour, order queueing | D19: =COUNTIF('3 T1 Command'!$I$15:$I$37,"Agreed")+COUNTIF('3 T1 Command'!$I$41:$I$50,"Agreed") -> 14 | E19: =COUNTIF('3 T1 Command'!$I$15:$I$37,"Proposed")+COUNTIF('3 T1 Command'!$I$41:$I$50,"Proposed") -> 8 | F19: =COUNTIF('3 T1 Command'!$I$15:$I$37,"Draft")+COUNTIF('3 T1 Command'!$I$41:$I$50,"Draft") -> 6 | G19: =COUNTIF('3 T1 Command'!$I$15:$I$37,"Needs detail")+COUNTIF('3 T1 Command'!$I$41:$I$50,"Needs detail") -> 0 | H19: =COUNTIF('3 T1 Command'!$I$15:$I$37,"Not started")+COUNTIF('3 T1 Command'!$I$41:$I$50,"Not started") -> 0 | I19: =SUM(D19:H19) -> 28 | J19: =IF(I19=0,0,D19/I19) -> 0.5 | K19: =COUNTIFS('3 T1 Command'!$I$15:$I$37,"Needs detail",'3 T1 Command'!$G$15:$G$37,"")+COUNTIFS('3 T1 Command'!$I$15:$I$37,"Not started",'3 T1 Command'!$G$15:$G$37,"")+COUNTIFS('3 T1 Command'!$I$41:$I$50,"Needs detail",'3 T1 Command'!$G$41:$G$50,"")+COUNTIFS('3 T1 Command'!$I$41:$I$50,"Not started",'3 T1 Command'!$G$41:$G$50,"") -> 0
A20: =HYPERLINK("#'4 T2 Grid'!A1","4 T2 Grid") -> 4 T2 Grid | B20: Terminals | C20: View levels, symbol legend, overlays, refresh | D20: =COUNTIF('4 T2 Grid'!$I$16:$I$19,"Agreed")+COUNTIF('4 T2 Grid'!$I$24:$I$39,"Agreed")+COUNTIF('4 T2 Grid'!$I$43:$I$52,"Agreed") -> 4 | E20: =COUNTIF('4 T2 Grid'!$I$16:$I$19,"Proposed")+COUNTIF('4 T2 Grid'!$I$24:$I$39,"Proposed")+COUNTIF('4 T2 Grid'!$I$43:$I$52,"Proposed") -> 21 | F20: =COUNTIF('4 T2 Grid'!$I$16:$I$19,"Draft")+COUNTIF('4 T2 Grid'!$I$24:$I$39,"Draft")+COUNTIF('4 T2 Grid'!$I$43:$I$52,"Draft") -> 0 | G20: =COUNTIF('4 T2 Grid'!$I$16:$I$19,"Needs detail")+COUNTIF('4 T2 Grid'!$I$24:$I$39,"Needs detail")+COUNTIF('4 T2 Grid'!$I$43:$I$52,"Needs detail") -> 0 | H20: =COUNTIF('4 T2 Grid'!$I$16:$I$19,"Not started")+COUNTIF('4 T2 Grid'!$I$24:$I$39,"Not started")+COUNTIF('4 T2 Grid'!$I$43:$I$52,"Not started") -> 0 | I20: =SUM(D20:H20) -> 25 | J20: =IF(I20=0,0,D20/I20) -> 0.16 | K20: =COUNTIFS('4 T2 Grid'!$I$16:$I$19,"Needs detail",'4 T2 Grid'!$G$16:$G$19,"")+COUNTIFS('4 T2 Grid'!$I$16:$I$19,"Not started",'4 T2 Grid'!$G$16:$G$19,"")+COUNTIFS('4 T2 Grid'!$I$24:$I$39,"Needs detail",'4 T2 Grid'!$G$24:$G$39,"")+COUNTIFS('4 T2 Grid'!$I$24:$I$39,"Not started",'4 T2 Grid'!$G$24:$G$39,"")+COUNTIFS('4 T2 Grid'!$I$43:$I$52,"Needs detail",'4 T2 Grid'!$G$43:$G$52,"")+COUNTIFS('4 T2 Grid'!$I$43:$I$52,"Not started",'4 T2 Grid'!$G$43:$G$52,"") -> 0
A21: =HYPERLINK("#'5 T3 Output'!A1","5 T3 Output") -> 5 T3 Output | B21: Terminals | C21: Message types, log behaviour | D21: =COUNTIF('5 T3 Output'!$I$15:$I$34,"Agreed")+COUNTIF('5 T3 Output'!$I$38:$I$43,"Agreed") -> 5 | E21: =COUNTIF('5 T3 Output'!$I$15:$I$34,"Proposed")+COUNTIF('5 T3 Output'!$I$38:$I$43,"Proposed") -> 5 | F21: =COUNTIF('5 T3 Output'!$I$15:$I$34,"Draft")+COUNTIF('5 T3 Output'!$I$38:$I$43,"Draft") -> 12 | G21: =COUNTIF('5 T3 Output'!$I$15:$I$34,"Needs detail")+COUNTIF('5 T3 Output'!$I$38:$I$43,"Needs detail") -> 0 | H21: =COUNTIF('5 T3 Output'!$I$15:$I$34,"Not started")+COUNTIF('5 T3 Output'!$I$38:$I$43,"Not started") -> 0 | I21: =SUM(D21:H21) -> 22 | J21: =IF(I21=0,0,D21/I21) -> 0.22727273 | K21: =COUNTIFS('5 T3 Output'!$I$15:$I$34,"Needs detail",'5 T3 Output'!$G$15:$G$34,"")+COUNTIFS('5 T3 Output'!$I$15:$I$34,"Not started",'5 T3 Output'!$G$15:$G$34,"")+COUNTIFS('5 T3 Output'!$I$38:$I$43,"Needs detail",'5 T3 Output'!$G$38:$G$43,"")+COUNTIFS('5 T3 Output'!$I$38:$I$43,"Not started",'5 T3 Output'!$G$38:$G$43,"") -> 0
A22: =HYPERLINK("#'5b T4 Status'!A1","5b T4 Status") -> 5b T4 Status | B22: Terminals | C22: Permanent status panels | D22: =COUNTIF('5b T4 Status'!$I$13:$I$20,"Agreed") -> 1 | E22: =COUNTIF('5b T4 Status'!$I$13:$I$20,"Proposed") -> 5 | F22: =COUNTIF('5b T4 Status'!$I$13:$I$20,"Draft") -> 0 | G22: =COUNTIF('5b T4 Status'!$I$13:$I$20,"Needs detail") -> 0 | H22: =COUNTIF('5b T4 Status'!$I$13:$I$20,"Not started") -> 0 | I22: =SUM(D22:H22) -> 6 | J22: =IF(I22=0,0,D22/I22) -> 0.16666667 | K22: =COUNTIFS('5b T4 Status'!$I$13:$I$20,"Needs detail",'5b T4 Status'!$G$13:$G$20,"")+COUNTIFS('5b T4 Status'!$I$13:$I$20,"Not started",'5b T4 Status'!$G$13:$G$20,"") -> 0
A23: =HYPERLINK("#'6 World Grids'!A1","6 World Grids") -> 6 World Grids | B23: World | C23: Grid hierarchy, cell contents, generation rules | D23: =COUNTIF('6 World Grids'!$H$7:$H$10,"Agreed")+COUNTIF('6 World Grids'!$H$14:$H$22,"Agreed") -> 6 | E23: =COUNTIF('6 World Grids'!$H$7:$H$10,"Proposed")+COUNTIF('6 World Grids'!$H$14:$H$22,"Proposed") -> 6 | F23: =COUNTIF('6 World Grids'!$H$7:$H$10,"Draft")+COUNTIF('6 World Grids'!$H$14:$H$22,"Draft") -> 0 | G23: =COUNTIF('6 World Grids'!$H$7:$H$10,"Needs detail")+COUNTIF('6 World Grids'!$H$14:$H$22,"Needs detail") -> 0 | H23: =COUNTIF('6 World Grids'!$H$7:$H$10,"Not started")+COUNTIF('6 World Grids'!$H$14:$H$22,"Not started") -> 0 | I23: =SUM(D23:H23) -> 12 | J23: =IF(I23=0,0,D23/I23) -> 0.5 | K23: =COUNTIFS('6 World Grids'!$H$7:$H$10,"Needs detail",'6 World Grids'!$F$7:$F$10,"")+COUNTIFS('6 World Grids'!$H$7:$H$10,"Not started",'6 World Grids'!$F$7:$F$10,"")+COUNTIFS('6 World Grids'!$H$14:$H$22,"Needs detail",'6 World Grids'!$F$14:$F$22,"")+COUNTIFS('6 World Grids'!$H$14:$H$22,"Not started",'6 World Grids'!$F$14:$F$22,"") -> 0
A24: =HYPERLINK("#'7 Stellar'!A1","7 Stellar") -> 7 Stellar | B24: World | C24: Stellar types, derived quantities, buckets, calculator | D24: =COUNTIF('7 Stellar'!$H$7:$H$10,"Agreed")+COUNTIF('7 Stellar'!$H$14:$H$19,"Agreed")+COUNTIF('7 Stellar'!$H$23:$H$26,"Agreed") -> 5 | E24: =COUNTIF('7 Stellar'!$H$7:$H$10,"Proposed")+COUNTIF('7 Stellar'!$H$14:$H$19,"Proposed")+COUNTIF('7 Stellar'!$H$23:$H$26,"Proposed") -> 7 | F24: =COUNTIF('7 Stellar'!$H$7:$H$10,"Draft")+COUNTIF('7 Stellar'!$H$14:$H$19,"Draft")+COUNTIF('7 Stellar'!$H$23:$H$26,"Draft") -> 0 | G24: =COUNTIF('7 Stellar'!$H$7:$H$10,"Needs detail")+COUNTIF('7 Stellar'!$H$14:$H$19,"Needs detail")+COUNTIF('7 Stellar'!$H$23:$H$26,"Needs detail") -> 0 | H24: =COUNTIF('7 Stellar'!$H$7:$H$10,"Not started")+COUNTIF('7 Stellar'!$H$14:$H$19,"Not started")+COUNTIF('7 Stellar'!$H$23:$H$26,"Not started") -> 0 | I24: =SUM(D24:H24) -> 12 | J24: =IF(I24=0,0,D24/I24) -> 0.41666667 | K24: =COUNTIFS('7 Stellar'!$H$7:$H$10,"Needs detail",'7 Stellar'!$F$7:$F$10,"")+COUNTIFS('7 Stellar'!$H$7:$H$10,"Not started",'7 Stellar'!$F$7:$F$10,"")+COUNTIFS('7 Stellar'!$H$14:$H$19,"Needs detail",'7 Stellar'!$F$14:$F$19,"")+COUNTIFS('7 Stellar'!$H$14:$H$19,"Not started",'7 Stellar'!$F$14:$F$19,"")+COUNTIFS('7 Stellar'!$H$23:$H$26,"Needs detail",'7 Stellar'!$F$23:$F$26,"")+COUNTIFS('7 Stellar'!$H$23:$H$26,"Not started",'7 Stellar'!$F$23:$F$26,"") -> 0
A25: =HYPERLINK("#'8 Hazards'!A1","8 Hazards") -> 8 Hazards | B25: World | C25: Gravity pull, shield drain, black holes, wormholes, calculator | D25: =COUNTIF('8 Hazards'!$I$7:$I$17,"Agreed") -> 5 | E25: =COUNTIF('8 Hazards'!$I$7:$I$17,"Proposed") -> 5 | F25: =COUNTIF('8 Hazards'!$I$7:$I$17,"Draft") -> 0 | G25: =COUNTIF('8 Hazards'!$I$7:$I$17,"Needs detail") -> 0 | H25: =COUNTIF('8 Hazards'!$I$7:$I$17,"Not started") -> 0 | I25: =SUM(D25:H25) -> 10 | J25: =IF(I25=0,0,D25/I25) -> 0.5 | K25: =COUNTIFS('8 Hazards'!$I$7:$I$17,"Needs detail",'8 Hazards'!$G$7:$G$17,"")+COUNTIFS('8 Hazards'!$I$7:$I$17,"Not started",'8 Hazards'!$G$7:$G$17,"") -> 0
A26: =HYPERLINK("#'9 Ships'!A1","9 Ships") -> 9 Ships | B26: Entities | C26: Ship attributes, movement, warp curve, classes | D26: =COUNTIF('9 Ships'!$H$7:$H$17,"Agreed")+COUNTIF('9 Ships'!$H$21:$H$27,"Agreed")+COUNTIF('9 Ships'!$H$52:$H$57,"Agreed") -> 7 | E26: =COUNTIF('9 Ships'!$H$7:$H$17,"Proposed")+COUNTIF('9 Ships'!$H$21:$H$27,"Proposed")+COUNTIF('9 Ships'!$H$52:$H$57,"Proposed") -> 11 | F26: =COUNTIF('9 Ships'!$H$7:$H$17,"Draft")+COUNTIF('9 Ships'!$H$21:$H$27,"Draft")+COUNTIF('9 Ships'!$H$52:$H$57,"Draft") -> 0 | G26: =COUNTIF('9 Ships'!$H$7:$H$17,"Needs detail")+COUNTIF('9 Ships'!$H$21:$H$27,"Needs detail")+COUNTIF('9 Ships'!$H$52:$H$57,"Needs detail") -> 1 | H26: =COUNTIF('9 Ships'!$H$7:$H$17,"Not started")+COUNTIF('9 Ships'!$H$21:$H$27,"Not started")+COUNTIF('9 Ships'!$H$52:$H$57,"Not started") -> 0 | I26: =SUM(D26:H26) -> 19 | J26: =IF(I26=0,0,D26/I26) -> 0.36842105 | K26: =COUNTIFS('9 Ships'!$H$7:$H$17,"Needs detail",'9 Ships'!$F$7:$F$17,"")+COUNTIFS('9 Ships'!$H$7:$H$17,"Not started",'9 Ships'!$F$7:$F$17,"")+COUNTIFS('9 Ships'!$H$21:$H$27,"Needs detail",'9 Ships'!$F$21:$F$27,"")+COUNTIFS('9 Ships'!$H$21:$H$27,"Not started",'9 Ships'!$F$21:$F$27,"")+COUNTIFS('9 Ships'!$H$52:$H$57,"Needs detail",'9 Ships'!$F$52:$F$57,"")+COUNTIFS('9 Ships'!$H$52:$H$57,"Not started",'9 Ships'!$F$52:$F$57,"") -> 1
A27: =HYPERLINK("#'10 Captain'!A1","10 Captain") -> 10 Captain | B27: Entities | C27: Captain attributes, fleet rules, endgame eligibility | D27: =COUNTIF('10 Captain'!$H$7:$H$17,"Agreed")+COUNTIF('10 Captain'!$H$21:$H$26,"Agreed")+COUNTIF('10 Captain'!$H$30:$H$38,"Agreed") -> 13 | E27: =COUNTIF('10 Captain'!$H$7:$H$17,"Proposed")+COUNTIF('10 Captain'!$H$21:$H$26,"Proposed")+COUNTIF('10 Captain'!$H$30:$H$38,"Proposed") -> 10 | F27: =COUNTIF('10 Captain'!$H$7:$H$17,"Draft")+COUNTIF('10 Captain'!$H$21:$H$26,"Draft")+COUNTIF('10 Captain'!$H$30:$H$38,"Draft") -> 0 | G27: =COUNTIF('10 Captain'!$H$7:$H$17,"Needs detail")+COUNTIF('10 Captain'!$H$21:$H$26,"Needs detail")+COUNTIF('10 Captain'!$H$30:$H$38,"Needs detail") -> 0 | H27: =COUNTIF('10 Captain'!$H$7:$H$17,"Not started")+COUNTIF('10 Captain'!$H$21:$H$26,"Not started")+COUNTIF('10 Captain'!$H$30:$H$38,"Not started") -> 0 | I27: =SUM(D27:H27) -> 23 | J27: =IF(I27=0,0,D27/I27) -> 0.56521739 | K27: =COUNTIFS('10 Captain'!$H$7:$H$17,"Needs detail",'10 Captain'!$F$7:$F$17,"")+COUNTIFS('10 Captain'!$H$7:$H$17,"Not started",'10 Captain'!$F$7:$F$17,"")+COUNTIFS('10 Captain'!$H$21:$H$26,"Needs detail",'10 Captain'!$F$21:$F$26,"")+COUNTIFS('10 Captain'!$H$21:$H$26,"Not started",'10 Captain'!$F$21:$F$26,"")+COUNTIFS('10 Captain'!$H$30:$H$38,"Needs detail",'10 Captain'!$F$30:$F$38,"")+COUNTIFS('10 Captain'!$H$30:$H$38,"Not started",'10 Captain'!$F$30:$F$38,"") -> 0
A28: =HYPERLINK("#'11 Items & Planets'!A1","11 Items & Planets") -> 11 Items & Planets | B28: Entities | C28: Items, element catalogue, planets | D28: =COUNTIF('11 Items & Planets'!$H$7:$H$12,"Agreed")+COUNTIF('11 Items & Planets'!$H$17:$H$24,"Agreed")+COUNTIF('11 Items & Planets'!$H$29:$H$43,"Agreed")+COUNTIF('11 Items & Planets'!$H$47:$H$53,"Agreed")+COUNTIF('11 Items & Planets'!$H$57:$H$62,"Agreed") -> 14 | E28: =COUNTIF('11 Items & Planets'!$H$7:$H$12,"Proposed")+COUNTIF('11 Items & Planets'!$H$17:$H$24,"Proposed")+COUNTIF('11 Items & Planets'!$H$29:$H$43,"Proposed")+COUNTIF('11 Items & Planets'!$H$47:$H$53,"Proposed")+COUNTIF('11 Items & Planets'!$H$57:$H$62,"Proposed") -> 21 | F28: =COUNTIF('11 Items & Planets'!$H$7:$H$12,"Draft")+COUNTIF('11 Items & Planets'!$H$17:$H$24,"Draft")+COUNTIF('11 Items & Planets'!$H$29:$H$43,"Draft")+COUNTIF('11 Items & Planets'!$H$47:$H$53,"Draft")+COUNTIF('11 Items & Planets'!$H$57:$H$62,"Draft") -> 0 | G28: =COUNTIF('11 Items & Planets'!$H$7:$H$12,"Needs detail")+COUNTIF('11 Items & Planets'!$H$17:$H$24,"Needs detail")+COUNTIF('11 Items & Planets'!$H$29:$H$43,"Needs detail")+COUNTIF('11 Items & Planets'!$H$47:$H$53,"Needs detail")+COUNTIF('11 Items & Planets'!$H$57:$H$62,"Needs detail") -> 0 | H28: =COUNTIF('11 Items & Planets'!$H$7:$H$12,"Not started")+COUNTIF('11 Items & Planets'!$H$17:$H$24,"Not started")+COUNTIF('11 Items & Planets'!$H$29:$H$43,"Not started")+COUNTIF('11 Items & Planets'!$H$47:$H$53,"Not started")+COUNTIF('11 Items & Planets'!$H$57:$H$62,"Not started") -> 0 | I28: =SUM(D28:H28) -> 35 | J28: =IF(I28=0,0,D28/I28) -> 0.4 | K28: =COUNTIFS('11 Items & Planets'!$H$7:$H$12,"Needs detail",'11 Items & Planets'!$F$7:$F$12,"")+COUNTIFS('11 Items & Planets'!$H$7:$H$12,"Not started",'11 Items & Planets'!$F$7:$F$12,"")+COUNTIFS('11 Items & Planets'!$H$17:$H$24,"Needs detail",'11 Items & Planets'!$F$17:$F$24,"")+COUNTIFS('11 Items & Planets'!$H$17:$H$24,"Not started",'11 Items & Planets'!$F$17:$F$24,"")+COUNTIFS('11 Items & Planets'!$H$29:$H$43,"Needs detail",'11 Items & Planets'!$F$29:$F$43,"")+COUNTIFS('11 Items & Planets'!$H$29:$H$43,"Not started",'11 Items & Planets'!$F$29:$F$43,"")+COUNTIFS('11 Items & Planets'!$H$47:$H$53,"Needs detail",'11 Items & Planets'!$F$47:$F$53,"")+COUNTIFS('11 Items & Planets'!$H$47:$H$53,"Not started",'11 Items & Planets'!$F$47:$F$53,"")+COUNTIFS('11 Items & Planets'!$H$57:$H$62,"Needs detail",'11 Items & Planets'!$F$57:$F$62,"")+COUNTIFS('11 Items & Planets'!$H$57:$H$62,"Not started",'11 Items & Planets'!$F$57:$F$62,"") -> 0
A29: =HYPERLINK("#'12 Trade & Economy'!A1","12 Trade & Economy") -> 12 Trade & Economy | B29: Rules | C29: Currencies, trade rules, upgrade map, sources and sinks | D29: =COUNTIF('12 Trade & Economy'!$H$7:$H$17,"Agreed")+COUNTIF('12 Trade & Economy'!$H$22:$H$27,"Agreed")+COUNTIF('12 Trade & Economy'!$H$32:$H$37,"Agreed") -> 17 | E29: =COUNTIF('12 Trade & Economy'!$H$7:$H$17,"Proposed")+COUNTIF('12 Trade & Economy'!$H$22:$H$27,"Proposed")+COUNTIF('12 Trade & Economy'!$H$32:$H$37,"Proposed") -> 3 | F29: =COUNTIF('12 Trade & Economy'!$H$7:$H$17,"Draft")+COUNTIF('12 Trade & Economy'!$H$22:$H$27,"Draft")+COUNTIF('12 Trade & Economy'!$H$32:$H$37,"Draft") -> 0 | G29: =COUNTIF('12 Trade & Economy'!$H$7:$H$17,"Needs detail")+COUNTIF('12 Trade & Economy'!$H$22:$H$27,"Needs detail")+COUNTIF('12 Trade & Economy'!$H$32:$H$37,"Needs detail") -> 0 | H29: =COUNTIF('12 Trade & Economy'!$H$7:$H$17,"Not started")+COUNTIF('12 Trade & Economy'!$H$22:$H$27,"Not started")+COUNTIF('12 Trade & Economy'!$H$32:$H$37,"Not started") -> 0 | I29: =SUM(D29:H29) -> 20 | J29: =IF(I29=0,0,D29/I29) -> 0.85 | K29: =COUNTIFS('12 Trade & Economy'!$H$7:$H$17,"Needs detail",'12 Trade & Economy'!$F$7:$F$17,"")+COUNTIFS('12 Trade & Economy'!$H$7:$H$17,"Not started",'12 Trade & Economy'!$F$7:$F$17,"")+COUNTIFS('12 Trade & Economy'!$H$22:$H$27,"Needs detail",'12 Trade & Economy'!$F$22:$F$27,"")+COUNTIFS('12 Trade & Economy'!$H$22:$H$27,"Not started",'12 Trade & Economy'!$F$22:$F$27,"")+COUNTIFS('12 Trade & Economy'!$H$32:$H$37,"Needs detail",'12 Trade & Economy'!$F$32:$F$37,"")+COUNTIFS('12 Trade & Economy'!$H$32:$H$37,"Not started",'12 Trade & Economy'!$F$32:$F$37,"") -> 0
A30: =HYPERLINK("#'13 Combat'!A1","13 Combat") -> 13 Combat | B30: Rules | C30: Combat model recommendation, outcomes, loot | D30: =COUNTIF('13 Combat'!$I$7:$I$11,"Agreed")+COUNTIF('13 Combat'!$I$16:$I$30,"Agreed") -> 6 | E30: =COUNTIF('13 Combat'!$I$7:$I$11,"Proposed")+COUNTIF('13 Combat'!$I$16:$I$30,"Proposed") -> 11 | F30: =COUNTIF('13 Combat'!$I$7:$I$11,"Draft")+COUNTIF('13 Combat'!$I$16:$I$30,"Draft") -> 0 | G30: =COUNTIF('13 Combat'!$I$7:$I$11,"Needs detail")+COUNTIF('13 Combat'!$I$16:$I$30,"Needs detail") -> 0 | H30: =COUNTIF('13 Combat'!$I$7:$I$11,"Not started")+COUNTIF('13 Combat'!$I$16:$I$30,"Not started") -> 0 | I30: =SUM(D30:H30) -> 17 | J30: =IF(I30=0,0,D30/I30) -> 0.35294118 | K30: =COUNTIFS('13 Combat'!$I$7:$I$11,"Needs detail",'13 Combat'!$G$7:$G$11,"")+COUNTIFS('13 Combat'!$I$7:$I$11,"Not started",'13 Combat'!$G$7:$G$11,"")+COUNTIFS('13 Combat'!$I$16:$I$30,"Needs detail",'13 Combat'!$G$16:$G$30,"")+COUNTIFS('13 Combat'!$I$16:$I$30,"Not started",'13 Combat'!$G$16:$G$30,"") -> 0
A31: =HYPERLINK("#'14 Fear & Respect'!A1","14 Fear & Respect") -> 14 Fear & Respect | B31: Rules | C31: Fear / respect events, level mechanics, effects | D31: =COUNTIF('14 Fear & Respect'!$I$8:$I$19,"Agreed")+COUNTIF('14 Fear & Respect'!$I$23:$I$28,"Agreed")+COUNTIF('14 Fear & Respect'!$I$33:$I$40,"Agreed") -> 8 | E31: =COUNTIF('14 Fear & Respect'!$I$8:$I$19,"Proposed")+COUNTIF('14 Fear & Respect'!$I$23:$I$28,"Proposed")+COUNTIF('14 Fear & Respect'!$I$33:$I$40,"Proposed") -> 14 | F31: =COUNTIF('14 Fear & Respect'!$I$8:$I$19,"Draft")+COUNTIF('14 Fear & Respect'!$I$23:$I$28,"Draft")+COUNTIF('14 Fear & Respect'!$I$33:$I$40,"Draft") -> 0 | G31: =COUNTIF('14 Fear & Respect'!$I$8:$I$19,"Needs detail")+COUNTIF('14 Fear & Respect'!$I$23:$I$28,"Needs detail")+COUNTIF('14 Fear & Respect'!$I$33:$I$40,"Needs detail") -> 0 | H31: =COUNTIF('14 Fear & Respect'!$I$8:$I$19,"Not started")+COUNTIF('14 Fear & Respect'!$I$23:$I$28,"Not started")+COUNTIF('14 Fear & Respect'!$I$33:$I$40,"Not started") -> 0 | I31: =SUM(D31:H31) -> 22 | J31: =IF(I31=0,0,D31/I31) -> 0.36363636 | K31: =COUNTIFS('14 Fear & Respect'!$I$8:$I$19,"Needs detail",'14 Fear & Respect'!$G$8:$G$19,"")+COUNTIFS('14 Fear & Respect'!$I$8:$I$19,"Not started",'14 Fear & Respect'!$G$8:$G$19,"")+COUNTIFS('14 Fear & Respect'!$I$23:$I$28,"Needs detail",'14 Fear & Respect'!$G$23:$G$28,"")+COUNTIFS('14 Fear & Respect'!$I$23:$I$28,"Not started",'14 Fear & Respect'!$G$23:$G$28,"")+COUNTIFS('14 Fear & Respect'!$I$33:$I$40,"Needs detail",'14 Fear & Respect'!$G$33:$G$40,"")+COUNTIFS('14 Fear & Respect'!$I$33:$I$40,"Not started",'14 Fear & Respect'!$G$33:$G$40,"") -> 0
A32: =HYPERLINK("#'15 Config Keys'!A1","15 Config Keys") -> 15 Config Keys | B32: Config | C32: Config keys for controls_config.ini | D32: =COUNTIF('15 Config Keys'!$K$8:$K$71,"Agreed") -> 17 | E32: =COUNTIF('15 Config Keys'!$K$8:$K$71,"Proposed") -> 43 | F32: =COUNTIF('15 Config Keys'!$K$8:$K$71,"Draft") -> 0 | G32: =COUNTIF('15 Config Keys'!$K$8:$K$71,"Needs detail") -> 0 | H32: =COUNTIF('15 Config Keys'!$K$8:$K$71,"Not started") -> 0 | I32: =SUM(D32:H32) -> 60 | J32: =IF(I32=0,0,D32/I32) -> 0.28333333 | K32: =COUNTIFS('15 Config Keys'!$K$8:$K$71,"Needs detail",'15 Config Keys'!$I$8:$I$71,"")+COUNTIFS('15 Config Keys'!$K$8:$K$71,"Not started",'15 Config Keys'!$I$8:$I$71,"") -> 0
A33: =HYPERLINK("#'16 Open Questions'!A1","16 Open Questions") -> 16 Open Questions | B33: Questions | C33: Open design questions, answers, resolution | D33: =COUNTIF('16 Open Questions'!$G$6:$G$45,"Agreed") -> 37 | E33: =COUNTIF('16 Open Questions'!$G$6:$G$45,"Proposed") -> 0 | F33: =COUNTIF('16 Open Questions'!$G$6:$G$45,"Draft") -> 0 | G33: =COUNTIF('16 Open Questions'!$G$6:$G$45,"Needs detail") -> 0 | H33: =COUNTIF('16 Open Questions'!$G$6:$G$45,"Not started") -> 0 | I33: =SUM(D33:H33) -> 37 | J33: =IF(I33=0,0,D33/I33) -> 1 | K33: —
A34: =HYPERLINK("#'17 Decisions'!A1","17 Decisions") -> 17 Decisions | B34: Decisions | C34: Decision log | D34: =COUNTIF('17 Decisions'!$F$6:$F$64,"Agreed") -> 53 | E34: =COUNTIF('17 Decisions'!$F$6:$F$64,"Proposed") -> 0 | F34: =COUNTIF('17 Decisions'!$F$6:$F$64,"Draft") -> 0 | G34: =COUNTIF('17 Decisions'!$F$6:$F$64,"Needs detail") -> 0 | H34: =COUNTIF('17 Decisions'!$F$6:$F$64,"Not started") -> 0 | I34: =SUM(D34:H34) -> 53 | J34: =IF(I34=0,0,D34/I34) -> 1 | K34: —
A35: =HYPERLINK("#'18 Build & Release'!A1","18 Build & Release") -> 18 Build & Release | B35: Delivery | C35: Repo, environment, packaging, distribution, build-kit files | D35: =COUNTIF('18 Build & Release'!$G$7:$G$13,"Agreed")+COUNTIF('18 Build & Release'!$G$17:$G$24,"Agreed")+COUNTIF('18 Build & Release'!$G$28:$G$39,"Agreed")+COUNTIF('18 Build & Release'!$G$44:$G$55,"Agreed") -> 17 | E35: =COUNTIF('18 Build & Release'!$G$7:$G$13,"Proposed")+COUNTIF('18 Build & Release'!$G$17:$G$24,"Proposed")+COUNTIF('18 Build & Release'!$G$28:$G$39,"Proposed")+COUNTIF('18 Build & Release'!$G$44:$G$55,"Proposed") -> 7 | F35: =COUNTIF('18 Build & Release'!$G$7:$G$13,"Draft")+COUNTIF('18 Build & Release'!$G$17:$G$24,"Draft")+COUNTIF('18 Build & Release'!$G$28:$G$39,"Draft")+COUNTIF('18 Build & Release'!$G$44:$G$55,"Draft") -> 0 | G35: =COUNTIF('18 Build & Release'!$G$7:$G$13,"Needs detail")+COUNTIF('18 Build & Release'!$G$17:$G$24,"Needs detail")+COUNTIF('18 Build & Release'!$G$28:$G$39,"Needs detail")+COUNTIF('18 Build & Release'!$G$44:$G$55,"Needs detail") -> 0 | H35: =COUNTIF('18 Build & Release'!$G$7:$G$13,"Not started")+COUNTIF('18 Build & Release'!$G$17:$G$24,"Not started")+COUNTIF('18 Build & Release'!$G$28:$G$39,"Not started")+COUNTIF('18 Build & Release'!$G$44:$G$55,"Not started") -> 9 | I35: =SUM(D35:H35) -> 33 | J35: =IF(I35=0,0,D35/I35) -> 0.51515152 | K35: =COUNTIFS('18 Build & Release'!$G$7:$G$13,"Needs detail",'18 Build & Release'!$E$7:$E$13,"")+COUNTIFS('18 Build & Release'!$G$7:$G$13,"Not started",'18 Build & Release'!$E$7:$E$13,"")+COUNTIFS('18 Build & Release'!$G$17:$G$24,"Needs detail",'18 Build & Release'!$E$17:$E$24,"")+COUNTIFS('18 Build & Release'!$G$17:$G$24,"Not started",'18 Build & Release'!$E$17:$E$24,"")+COUNTIFS('18 Build & Release'!$G$28:$G$39,"Needs detail",'18 Build & Release'!$E$28:$E$39,"")+COUNTIFS('18 Build & Release'!$G$28:$G$39,"Not started",'18 Build & Release'!$E$28:$E$39,"")+COUNTIFS('18 Build & Release'!$G$44:$G$55,"Needs detail",'18 Build & Release'!$E$44:$E$55,"")+COUNTIFS('18 Build & Release'!$G$44:$G$55,"Not started",'18 Build & Release'!$E$44:$E$55,"") -> 8
A36: =HYPERLINK("#'Source v1'!A1","Source v1") -> Source v1 | B36: Source | C36: Original blueprint, verbatim, plus chat addendum | D36: — | E36: — | F36: — | G36: — | H36: — | I36: — | J36: — | K36: —
A37: Total | D37: =SUM(D17:D36) -> 257 | E37: =SUM(E17:E36) -> 191 | F37: =SUM(F17:F36) -> 22 | G37: =SUM(G17:G36) -> 1 | H37: =SUM(H17:H36) -> 9 | I37: =SUM(I17:I36) -> 480 | J37: =IF(I37=0,0,D37/I37) -> 0.53541667 | K37: =SUM(K17:K36) -> 9
A39: Legend
A40: Yellow cell | B40: Yours to fill in or decide — or an input to a calculator (7 Stellar, 8 Hazards, 9 Ships).
A41: Status | B41: Agreed = decided by you (ready for a spec) · Proposed = Claude's proposal from your answers, awaiting your yes · Draft = from your blueprint, not yet confirmed · Needs detail = a follow-up question is open in chat · Not started = nothing decided.
A42: Origin | B42: BP rNN = your blueprint row on 'Source v1' · Chat An = your words in chat (addendum) · Ans Q-xx = your answer on tab 16 · Claude = Claude's proposal · Implied rNN = inferred from that row · Project = Project instructions.
A43: Open Q | B43: Q-xx = a row on '16 Open Questions'. Every question now has a resolution column saying where its answer went.
...

Sheet 1 Overview
A1: 1 · Overview
A2: What the game is, what the player is trying to do, and how a turn runs
A3: =HYPERLINK("#'0 Index'!A1","↩ Index") -> ↩ Index
A5: Concept
A6: ID | B6: Topic | C6: Statement | D6: Open Q | E6: Origin | F6: Status
A7: OV-01 | B7: Format | C7: Text-based game played in terminals. Colourful throughout — every terminal uses colour (Rich). | E7: BP r3; Chat A8 | F7: Agreed
A8: OV-02 | B8: Turn structure | C8: Turn-based: the player queues any number of orders, then ends the turn; all captains' orders resolve simultaneously in the fixed phase order below. | D8: Q-01 | E8: BP r4; Ans Q-01 | F8: Agreed
A9: OV-02b | B9: Immediate vs queued | C9: Immediate (no turn needed): help, status, fleet, ship, view, orders, scan. Queued until 'end': move, warp, fire, shields, peace, escape, trade, upgrade, pickup. A second queued order of the same kind for the same ship replaces the first. | D9: Q-01 | E9: Claude | F9: Proposed
A10: OV-03 | B10: Player role | C10: The player is the captain of their ship. | E10: BP r9 | F10: Draft
A11: OV-04 | B11: Exploration | C11: Starts with one starship and explores the universe: Universe → Galaxies → Sectors → stars / planets / ships / objects. | E11: BP r8 | F11: Draft
A12: OV-05 | B12: Combat | C12: Ships (and planets) can battle each other (13 Combat). | D12: Q-12 | E12: BP r10; Ans Q-21 | F12: Draft
A13: OV-06 | B13: Progression | C13: Captains gain wealth (gold and silver), items, fear and respect. | E13: BP r11, r80 | F13: Draft
A14: OV-07 | B14: Endgame — becoming Master of Starbour | C14: When respect and fear both reach the threshold (e.g. 90 of 100) and the captain holds enough gold and silver, they become eligible to find the ultimate secret item, guarded by ships in a far-away sector. Obtaining it makes them Master of Starbour: max warp, weapons, shields, engine; infinite wealth; respect and fear at maximum; all planets willing to trade. | D14: Q-15, Q-26 | E14: BP r12; Ans Q-15, Q-26, Q-37 | F14: Agreed
A15: OV-08 | B15: Fleet | C15: A captain may own several ships (no limit) and switch between them from the command terminal. | D15: Q-13 | E15: BP r13; Ans Q-13 | F15: Agreed
A16: OV-09 | B16: Win condition | C16: The game does not end. Mastery triggers a celebration and ceremony, then play carries on with the max powers. | D16: Q-16 | E16: Chat A4 | F16: Agreed
A17: OV-09b | B17: Lose condition | C17: Game over only when the player's active ship is destroyed (the captain is on it); the player starts again. | D17: Q-29 | E17: Chat A6, A10; Ans Q-29 | F17: Agreed
A18: OV-09c | B18: 'Start again' | C18: New game = new seed; the save is deleted on game over. | D18: Q-33 | E18: Ans Q-33 | F18: Agreed
A19: OV-10 | B19: Opponents | C19: Other captains are AI-controlled; they trade, battle, offer peace and progress. Count per galaxy is a config key. | D19: Q-13 | E19: Implied r90; Claude | F19: Proposed
A20: OV-11 | B20: Pacing | C20: No fixed turn counts. Rough feel only: a battle every 5–7 turns on average; mastery a long way off. Every number in this workbook is a placeholder tuned by playtest — 'what is appropriate and what works'. | D20: Q-35 | E20: Ans Q-35; Chat A15, A16 | F20: Agreed
A21: OV-12 | B21: Save / load | C21: Autosave every turn, one slot per game, save deleted on game over. Location: next to the exe. | D21: Q-33 | E21: Ans Q-33, Q-28 | F21: Agreed
A22: OV-13 | B22: Starbour | C22: 'Starbour' is a play on harbour / starship — not the universe's name. 'Master of Starbour' is the title won with the ultimate secret item. | D22: Q-26 | E22: Ans Q-26 | F22: Agreed
A26: Turn resolution order
A27: Agreed as option A of Q-01: all captains' orders resolve together, in this fixed order.
A28: ID | B28: Phase | C28: What resolves | D28: Open Q | E28: Origin | F28: Status
A29: TP-01 | B29: 1 Orders | C29: Player and AI captains queue orders; the player ends the turn. | E29: BP r4; Ans Q-01 | F29: Agreed
A30: TP-02 | B30: 2 Movement | C30: Impulse and warp moves resolve (effective speed = nominal − gravity pull). | D30: Q-02 | E30: Ans Q-02 | F30: Agreed
A31: TP-03 | B31: 3 Hazards | C31: Gravity countdowns and shield drain apply (8 Hazards). | E31: Implied r65–72 | F31: Agreed
A32: TP-04 | B32: 4 Combat | C32: Battles resolve one exchange per turn: destroy / escape / peace (13 Combat). | D32: Q-12 | E32: Claude | F32: Proposed
A33: TP-05 | B33: 5 Trade & pickup | C33: Accepted trades settle; upgrades apply; item pickups happen. | E33: Ans Q-07, Q-14 | F33: Agreed
A34: TP-06 | B34: 6 Upkeep | C34: Food and water −1 each; mutiny check (SUP-03); shields recharge if not in a hazard or battle. | D34: Q-19 | E34: Ans Q-19; Chat A11; Claude | F34: Proposed
A35: TP-07 | B35: 7 Reputation | C35: Fear and respect deltas apply (14 Fear & Respect). | E35: Implied r94–103 | F35: Agreed
A36: TP-08 | B36: 8 Publish & render | C36: turn.resolved on the bus; T2, T3 and T4 redraw once; autosave. | D36: Q-31 | E36: Ans Q-31, Q-33 | F36: Agreed

Sheet 2 Architecture
A1: 2 · Architecture
A2: Terminals, the message bus, processes and the message catalogue
A3: =HYPERLINK("#'0 Index'!A1","↩ Index") -> ↩ Index
A5: Terminals
A6: ID | B6: Terminal | C6: Role | D6: Detail tab | E6: Open Q | F6: Origin | G6: Status
A7: T1 | B7: Command | C7: Player types orders, switches ships, changes the grid view, ends the turn. | D7: 3 T1 Command | F7: BP r17 | G7: Agreed
A8: T2 | B8: Grid | C8: Map at Universe, Galaxy or Sector level; auto-follows the active ship, 'view' overrides. | D8: 4 T2 Grid | E8: Q-17 | F8: BP r18; Ans Q-17 | G8: Agreed
A9: T3 | B9: Output | C9: Results, reports, log. | D9: 5 T3 Output | F9: BP r19 | G9: Agreed
A10: T4 | B10: Status | C10: Permanent status panel: captain, active ship, fleet, cargo. | D10: 5b T4 Status | E10: Q-25 | F10: Ans Q-25 | G10: Agreed
A11: T0 | B11: Engine | C11: Owns the game state; resolves turns; publishes state. Its own process, no window (or a hidden console). | D11: — | E11: Q-18 | F11: Ans Q-18 | G11: Agreed
A12: TL | B12: Launcher | C12: Starts the engine and the four terminals; owns them; closing T1 or the launcher ends the game and kills the rest; closing T2 / T3 / T4 reopens it. | D12: 18 Build & Release | E12: Q-32 | F12: Ans Q-32 | G12: Agreed
A14: Bus & processes
A15: ID | B15: Topic | C15: Statement | D15: Notes | E15: Open Q | F15: Origin | G15: Status
A16: BUS-01 | B16: Transport | C16: A message bus connects all processes. | F16: BP r21 | G16: Agreed
A17: BUS-02 | B17: Process model | C17: One process per terminal plus the engine; threads within each. | D17: Project fixed fact. | F17: Project | G17: Agreed
A18: BUS-03 | B18: Technology | C18: ZeroMQ (pyzmq) over localhost TCP: engine PUB → terminals SUB for state; T1 PUSH → engine PULL for orders. | D18: Ports are config keys. | E18: Q-18 | F18: Ans Q-18 | G18: Agreed
A19: BUS-04 | B19: Single owner of state | C19: The engine process is the only writer of game state; terminals are views. | E19: Q-18 | F19: Ans Q-18 | G19: Agreed
A20: BUS-05 | B20: Refresh model | C20: Terminals redraw once per turn.resolved, full redraw, target under 0.5 s. | E20: Q-31 | F20: Ans Q-31 | G20: Agreed
A21: BUS-06 | B21: Startup / shutdown | C21: Launcher owns child processes; 'quit' or closing T1 → engine saves, launcher terminates all children; no orphans. | D21: Build gates: 'orphaned processes', 'exe opens and exits'. | E21: Q-32 | F21: Ans Q-32 | G21: Agreed
A22: BUS-07 | B22: Snapshot vs delta | C22: state.updated carries a full snapshot each turn (simplest; sizes are small). | D22: Revisit only if redraw exceeds 0.5 s. | E22: Q-31 | F22: Claude | G22: Proposed
A25: Message catalogue
A26: Payload fields are proposals; rename freely.
A27: ID | B27: Message | C27: Publisher → Subscribers | D27: Payload (fields) | E27: Open Q | F27: Origin | G27: Status
A28: MSG-01 | B28: order.submitted | C28: T1 → Engine | D28: command, args, ship_id, turn_no | F28: Claude | G28: Proposed
A29: MSG-02 | B29: turn.end | C29: T1 → Engine | D29: turn_no | F29: Claude | G29: Proposed
A30: MSG-03 | B30: turn.resolved | C30: Engine → T2, T3, T4 | D30: turn_no, full state snapshot, events[] | E30: Q-31 | F30: Ans Q-31; Claude | G30: Proposed
A31: MSG-04 | B31: view.changed | C31: T1 → T2 | D31: level (universe / galaxy / sector), focus coordinates | F31: Claude | G31: Proposed
A32: MSG-05 | B32: event.log | C32: Engine → T3 | D32: type, text, severity, turn_no (also inside turn.resolved) | F32: Claude | G32: Proposed
A33: MSG-06 | B33: order.rejected | C33: Engine → T1, T3 | D33: order, reason | E33: Q-34 | F33: Ans Q-34 | G33: Proposed
A34: MSG-07 | B34: order.accepted | C34: Engine → T1 | D34: order, queue position | F34: Claude | G34: Proposed
A35: MSG-08 | B35: system.shutdown | C35: Launcher → all | D35: reason | E35: Q-32 | F35: Ans Q-32 | G35: Proposed
A36: MSG-09 | B36: game.over / game.mastery | C36: Engine → all | D36: cause / ceremony payload | E36: Q-37 | F36: Claude | G36: Proposed
A40: Diagram — every process talks only to the bus
B42: ZeroMQ bus (localhost)
B43: ▲ ▼ | C43: ▲ ▼ | D43: ▲ ▼ | E43: ▲ ▼ | F43: ▲ ▼
B44: T2 Grid | C44: T3 Output | D44: T4 Status | E44: T1 Command | F44: T0 Engine
B46: Launcher starts and owns all six processes (Q-32).

Sheet 3 T1 Command
A1: 3 · T1 Command terminal
A2: The input terminal: every command the player can type, and how the prompt behaves
A3: =HYPERLINK("#'0 Index'!A1","↩ Index") -> ↩ Index
A5: Purpose | C5: Where the player types orders, switches ships, changes the grid view and ends the turn. | I5: BP r17, r13, r18
A6: Process / module | C6: TBD — e.g. mos/terminals/command.py | I6: Template
A7: Input style | C7: Free-text command line with history and tab completion. | I7: Claude · Proposed
A8: Publishes | C8: order.submitted, turn.end, view.changed | I8: 2 Architecture
A9: Subscribes | C9: order.accepted, order.rejected, turn.resolved (unlocks the prompt) | I9: Ans Q-34
A10: Library | C10: Rich (colour output) + prompt_toolkit (input) | I10: Claude · Proposed
A12: Command catalogue
A13: Immediate = acts at once. Queued = waits for 'end'. Rename freely.
A14: ID | B14: Command | C14: Syntax | D14: What it does | E14: When valid | F14: Feedback / errors | G14: Open Q | H14: Origin | I14: Status
A15: CMD-01 | B15: help | C15: help [command] | D15: Lists commands, or shows one command's syntax. | E15: Immediate | H15: Template | I15: Draft
A16: CMD-02 | B16: status | C16: status | D16: Shows the active ship's stats and the captain's wealth, fear, respect, food and water. | E16: Immediate | H16: Implied r75, r80 | I16: Draft
A17: CMD-03 | B17: ship | C17: ship <name | n> | D17: Switches the active ship. | E17: Immediate; captain owns more than one ship | F17: Error if unknown | G17: Q-13 | H17: BP r13 | I17: Agreed
A18: CMD-04 | B18: fleet | C18: fleet | D18: Lists all owned ships, their locations and state. | E18: Immediate | G18: Q-13 | H18: Implied r13 | I18: Draft
A19: CMD-05 | B19: view | C19: view universe | galaxy | sector | follow | D19: Changes the Grid terminal level; 'follow' returns to auto-follow. | E19: Immediate | G19: Q-17 | H19: BP r18; Ans Q-17 | I19: Agreed
A20: CMD-06 | B20: move | C20: move <dx dy | x y> [speed] | D20: Impulse move within the sector. speed ≤ engine_power; cells moved = floor(speed − gravity pull). | E20: Queued | F20: Reject if speed > engine_power or target outside the sector | G20: Q-02 | H20: Ans Q-02 | I20: Agreed
A21: CMD-07 | B21: warp | C21: warp <gx gy> <sx sy> [factor] | D21: Warp to a sector (in any galaxy). factor ≤ warpcore_power; reach from the warp curve (9 Ships). | E21: Queued | F21: Reject if destination beyond reach for the factor | G21: Q-02 | H21: Ans Q-02 | I21: Agreed
A22: CMD-08 | B22: fire | C22: fire torpedo | phaser <target> | D22: Attacks a ship or planet in range. Starting a fight costs respect; asks for confirmation. | E22: Queued; target in range | F22: Confirm (Q-34) | G22: Q-12 | H22: Implied r75, r100; Ans Q-34 | I22: Agreed
A23: CMD-09 | B23: shields | C23: shields status | D23: Shows current / max shields. Shield power is not adjustable — it drains and recharges. | E23: Immediate | G23: Q-12 | H23: Claude | I23: Proposed
A24: CMD-10 | B24: peace | C24: peace offer | accept | reject <captain | planet> | D24: Offers, accepts or rejects peace during a battle. | E24: Queued; during a battle | G24: Q-12 | H24: Implied r99, r108 | I24: Draft
A25: CMD-11 | B25: escape | C25: escape <dx dy> | D25: Moves out of all enemies' weapon range; succeeds if the move completes (no dice). | E25: Queued; during a battle | G25: Q-12 | H25: Claude | I25: Proposed
A26: CMD-12 | B26: trade | C26: trade <captain | planet> give <items> for <items> | D26: Proposes a trade of items, gold or silver. 1 gold = 20 silver. | E26: Queued; counterparty in the same cell | G26: Q-14 | H26: Ans Q-14; Claude | I26: Proposed
A27: CMD-13 | B27: upgrade | C27: upgrade <component> with <element> | D27: Spends an element to improve torpedoes, phasers, shields, engine or warp core (12 Trade, upgrade map). | E27: Queued | F27: Reject if the element does not improve that component | G27: Q-14 | H27: BP r91 | I27: Draft
A28: CMD-14 | B28: scan | C28: scan | D28: Reveals what is in the current cell (items) and, with fog of war on, the surrounding sector. | E28: Immediate | G28: Q-07, Q-30 | H28: Ans Q-07, Q-30 | I28: Agreed
A29: CMD-15 | B29: pickup | C29: pickup <item> | D29: Picks up an item in the current cell after a scan. Items are never picked up automatically. | E29: Queued; item in cell and scanned | G29: Q-07 | H29: Ans Q-07 | I29: Agreed
A30: CMD-16 | B30: orders | C30: orders [cancel n] | D30: Reviews or cancels queued orders before the turn ends. | E30: Immediate | G30: Q-01 | H30: Template | I30: Draft
A31: CMD-17 | B31: end | C31: end | D31: Ends the turn; all queued orders execute. | E31: Immediate | F31: Confirm if a hazard countdown is running and no move is queued | G31: Q-01, Q-34 | H31: BP r4 | I31: Agreed
A32: CMD-18 | B32: quit | C32: quit | D32: Confirms, autosaves, then the launcher closes every window. | E32: Immediate | F32: Confirm | G32: Q-32, Q-34 | H32: Ans Q-32, Q-34 | I32: Agreed
A33: CMD-19 | B33: new | C33: new [seed] | D33: Starts a new game (new seed). Offered after game over; also available any time with confirmation. | E33: Immediate | F33: Confirm | G33: Q-33 | H33: Ans Q-33 | I33: Agreed
A34: CMD-20 | B34: buy / sell | C34: buy <item> <qty> / sell <item> <qty> | D34: Buys from or sells to the planet in the current cell at its prices (shortcut for trade with a planet). | E34: Queued; planet in cell | G34: Q-14 | H34: Ans Q-14; Claude | I34: Proposed
A39: Prompt & interaction
A40: ID | B40: Aspect | C40: Current thinking | D40: Example | E40: Edge cases | F40: Notes | G40: Open Q | H40: Origin | I40: Status
A41: UX-01 | B41: Prompt format | C41: Turn number, active ship, queued-order count. | D41: [T12 · Kestrel · 2 orders] > | H41: Claude | I41: Proposed
A42: UX-02 | B42: Many orders per turn | C42: Orders are queued, then 'end' executes them all. | E42: Same-kind order for the same ship replaces the earlier one (OV-02b). | G42: Q-01 | H42: BP r4; Ans Q-01 | I42: Agreed
A43: UX-03 | B43: Error display | C43: Rejected orders and invalid commands show inline on T1 and are echoed to the T3 log. | G43: Q-34 | H43: Ans Q-34 | I43: Agreed
A44: UX-04 | B44: Confirmations | C44: Confirm before: starting a fight, quit, new game, ending a turn inside a hazard with no move queued. | G44: Q-34 | H44: Ans Q-34 | I44: Agreed
A45: UX-05 | B45: History / autocomplete | C45: Arrow-key history; tab completion of commands, ship, captain and planet names. | H45: Claude | I45: Proposed
A46: UX-06 | B46: Waiting for resolution | C46: Prompt locks after 'end' and shows a spinner until turn.resolved. | H46: Claude | I46: Proposed
...

Sheet 4 T2 Grid
A1: 4 · T2 Grid terminal
A2: The map: levels, symbol legend, overlays and refresh
A3: =HYPERLINK("#'0 Index'!A1","↩ Index") -> ↩ Index
A5: Purpose | C5: Shows the map at Universe, Galaxy or Sector level; auto-follows the active ship, 'view' overrides. | I5: BP r18; Ans Q-17
A6: Process / module | C6: TBD — e.g. mos/terminals/grid.py | I6: Template
A7: Subscribes | C7: turn.resolved, view.changed | I7: 2 Architecture
A8: Publishes | C8: nothing (display only) | I8: Claude · Proposed
A9: Render library | C9: Rich — full-colour cells | I9: Chat A8 · Proposed
A10: Refresh | C10: Full redraw once per turn.resolved and on view.changed | I10: Ans Q-31
A11: Fog of war | C11: Config key [world] fog_of_war = on | off. On: sector contents hidden until visited or scanned; galaxy / universe layout always visible. | I11: Ans Q-30
A13: View levels
A14: Default sizes are proposals; all three are config keys (Q-05).
A15: ID | B15: Level | C15: Each cell shows | D15: Grid size (M × N) | E15: Highlights | F15: Cell format | G15: Open Q | H15: Origin | I15: Status
A16: VW-01 | B16: Universe | C16: A galaxy or Void. | D16: 8 × 8 galaxies | E16: Galaxy containing the active ship | F16: 2 chars + colour | G16: Q-05 | H16: BP r35–36; Claude | I16: Proposed
A17: VW-02 | B17: Galaxy | C17: A sector or Void. | D17: 16 × 16 sectors | E17: Sector containing the active ship; sectors with known hazards | F17: 2 chars + colour | G17: Q-05 | H17: BP r39–40; Claude | I17: Proposed
A18: VW-03 | B18: Sector | C18: A star / black hole / neutron star / planet, items, ships, or Void. | D18: 24 × 24 cells | E18: Active ship; owned ships; enemy ships; hazard cells | F18: 2 chars + colour | G18: Q-05, Q-06 | H18: BP r43–44; Claude | I18: Proposed
A21: Symbol legend
A22: Glyphs are proposals. Star colours follow the real stellar sequence from temperature (7 Stellar).
A23: ID | B23: Object | C23: Glyph | D23: Colour | E23: Colour rule | F23: Notes | G23: Open Q | H23: Origin | I23: Status
A24: SYM-01 | B24: Void | C24: · | D24: dark grey | H24: Claude | I24: Proposed
A25: SYM-02 | B25: Galaxy (universe view) | C25: ◎ | D25: white | H25: Claude | I25: Proposed
A26: SYM-03 | B26: Sector (galaxy view) | C26: ▪ | D26: grey; cyan if visited | G26: Q-30 | H26: Claude | I26: Proposed
A27: SYM-04 | B27: Star | C27: ★ | D27: by temperature | E27: red < 3 700 K · orange < 5 200 · yellow < 6 000 · yellow-white < 7 500 · white < 10 000 · blue-white < 30 000 · blue above | F27: Thresholds are config keys | G27: Q-10 | H27: BP r53–55, r111; Claude | I27: Proposed
A28: SYM-05 | B28: Neutron star | C28: ✦ | D28: magenta | F28: Pulls across the sector, weaker than a black hole | G28: Q-09 | H28: Ans Q-09 | I28: Proposed
A29: SYM-06 | B29: Black hole | C29: ● | D29: bright red | F29: Whole-sector hazard | H29: Claude | I29: Proposed
A30: SYM-07 | B30: Wormhole | C30: ◉ | D30: purple | F30: A black hole with a fixed partner | G30: Q-11 | H30: Ans Q-11 | I30: Proposed
A31: SYM-08 | B31: Planet | C31: ○ | D31: green | H31: Claude | I31: Proposed
A32: SYM-09 | B32: Item (normal / special) | C32: ? / ✧ | D32: yellow / bright yellow | F32: Shown only after a scan when fog of war is on | G32: Q-07 | H32: Ans Q-07 | I32: Proposed
A33: SYM-10 | B33: Active ship (player) | C33: ▲ | D33: bright cyan | H33: Claude | I33: Proposed
A34: SYM-11 | B34: Other owned ship | C34: △ | D34: cyan | G34: Q-13 | H34: Claude | I34: Proposed
A35: SYM-12 | B35: AI captain's ship | C35: ▼ | D35: orange; red when in battle with you | H35: Claude | I35: Proposed
A36: SYM-13 | B36: Binary / triple star | C36: ★★ | D36: each by its own temperature | F36: Stars are always in separate cells (Q-06); a system = stars in adjacent cells | G36: Q-06 | H36: Ans Q-06 | I36: Agreed
A37: SYM-14 | B37: Several things in one cell | C37: ship glyph wins | E37: Priority: active ship > other ship > item > terrain | F37: Only one star / planet / hole per cell | G37: Q-06 | H37: Ans Q-06; Claude | I37: Proposed
A41: Overlays & behaviour
A42: ID | B42: Aspect | C42: Current thinking | D42: Example | E42: Edge cases | F42: Notes | G42: Open Q | H42: Origin | I42: Status
A43: GRD-01 | B43: Coordinates | C43: Zero-based x y, column labels along the top, row labels down the side; commands use the same numbers. | D43: move 12 7 | G43: Q-05 | H43: Claude | I43: Proposed
A44: GRD-02 | B44: Level switching | C44: Auto-follows the active ship (sector view); 'view' overrides until 'view follow'. | G44: Q-17 | H44: Ans Q-17 | I44: Agreed
A45: GRD-03 | B45: Hazard overlay | C45: Cells within pull range are tinted; the countdown (turns until pulled in) is shown next to the ship. | G45: Q-02 | H45: Claude | I45: Proposed
A46: GRD-04 | B46: Fog of war | C46: Config on / off (see header). | G46: Q-30 | H46: Ans Q-30 | I46: Agreed
A47: GRD-05 | B47: Viewport | C47: Grid is sized to fit the window at the default sizes; larger configs scroll centred on the ship. | G47: Q-05 | H47: Claude | I47: Proposed
...

Sheet 5 T3 Output
A1: 5 · T3 Output terminal
A2: Results, reports and the event log
A3: =HYPERLINK("#'0 Index'!A1","↩ Index") -> ↩ Index
A5: Purpose | C5: Shows results, reports and information — the event log. | I5: BP r19
A6: Process / module | C6: TBD — e.g. mos/terminals/output.py | I6: Template
A7: Subscribes | C7: turn.resolved, event.log, order.rejected | I7: 2 Architecture
A8: Publishes | C8: nothing (display only) | I8: Claude · Proposed
A9: Render library | C9: Rich — colour per severity | I9: Chat A8
A10: Scrollback | C10: Last 500 lines kept; grouped by phase within a turn | I10: Claude · Proposed
A12: Message types
A13: 'Example line' is where you write what it should actually look like.
A14: ID | B14: Message type | C14: Triggered by | D14: Content (fields) | E14: Example line | F14: Severity / colour | G14: Open Q | H14: Origin | I14: Status
A15: OUT-01 | B15: Turn summary | C15: Turn resolved | D15: turn no, orders executed, notable events | E15: TBD | F15: Info | H15: Implied r4 | I15: Draft
A16: OUT-02 | B16: Movement result | C16: Move / warp resolved | D16: ship, from, to, speed / factor, pull netted | E16: TBD | F16: Info | G16: Q-02 | H16: Ans Q-02 | I16: Draft
A17: OUT-03 | B17: Hazard warning | C17: Ship within pull range | D17: object, pull, turns until pulled in, shield drain this turn | E17: TBD | F17: Warning (yellow) | G17: Q-02 | H17: Ans Q-02 | I17: Draft
A18: OUT-04 | B18: Combat report | C18: Battle exchange resolved | D18: attacker, defender, weapon, hit / miss, damage, shields left | E18: TBD | F18: Alert (red) | G18: Q-12 | H18: Claude | I18: Proposed
A19: OUT-05 | B19: Peace / escape | C19: Peace offered / accepted / rejected; escape attempted | D19: parties, result, X% transferred | E19: TBD | F19: Alert | G19: Q-12 | H19: Implied r107–108 | I19: Draft
A20: OUT-06 | B20: Loot acquired | C20: Opponent destroyed, or peace settlement | D20: items, gold, silver, stat gains | E20: TBD | F20: Info (green) | G20: Q-12 | H20: Implied r106 | I20: Draft
A21: OUT-07 | B21: Trade result | C21: Trade / buy / sell accepted or rejected | D21: counterparty, given, received | E21: TBD | F21: Info | G21: Q-14 | H21: Ans Q-14 | I21: Draft
A22: OUT-08 | B22: Upgrade applied | C22: Element used on a component | D22: component, before → after | E22: TBD | F22: Info | G22: Q-14 | H22: Implied r91 | I22: Draft
A23: OUT-09 | B23: Fear / respect change | C23: Any control event | D23: event, Δ fear, Δ respect, new levels | E23: TBD | F23: Info | H23: Implied r94–103 | I23: Draft
A24: OUT-10 | B24: Scan result / item found | C24: scan; pickup | D24: items in cell, hazards nearby | E24: TBD | F24: Info | G24: Q-07 | H24: Ans Q-07 | I24: Draft
A25: OUT-11 | B25: Ship lost / fleet change | C25: Ship destroyed, acquired or switched | D25: ship, cause | E25: TBD | F25: Alert | G25: Q-13 | H25: Implied r13 | I25: Draft
A26: OUT-12 | B26: Endgame eligibility | C26: Thresholds reached | D26: which thresholds; where the guarded sector is | E26: TBD | F26: Highlight | G26: Q-15 | H26: Ans Q-15 | I26: Draft
A27: OUT-13 | B27: Invalid command / rejected order | C27: Bad input, impossible order | D27: message, reason (echo of T1) | E27: TBD | F27: Error | G27: Q-34 | H27: Ans Q-34 | I27: Agreed
A28: OUT-14 | B28: System | C28: Bus connected, saved, AI thinking, shutdown | D28: message | E28: TBD | F28: Muted | G28: Q-32 | H28: Ans Q-32 | I28: Draft
A29: OUT-15 | B29: Mastery ceremony | C29: Ultimate item obtained | D29: fireworks animation, big ASCII-art title, stats maxed, planets open | E29: TBD | F29: Highlight (full colour) | G29: Q-37 | H29: Ans Q-37 | I29: Agreed
A30: OUT-16 | B30: Game over | C30: Player's ship destroyed | D30: cause, turn reached, run summary, 'new' to start again | E30: TBD | F30: Alert | G30: Q-29 | H30: Ans Q-29 | I30: Agreed
A31: OUT-17 | B31: Supplies warning | C31: Food or water ≤ warn_turns, or at 0 | D31: turns left, turns until mutiny | E31: TBD | F31: Warning | G31: Q-19 | H31: Ans Q-19; Claude | I31: Proposed
A32: OUT-18 | B32: Mutiny | C32: Food or water at 0 for mutiny_turns_at_zero turns | D32: ship lost; moved to <ship> or demoted to a Kestrel; supplies given; fear change | E32: TBD | F32: Alert | G32: Q-19 | H32: Chat A11, A19 | I32: Agreed
A36: Behaviour
A37: ID | B37: Aspect | C37: Current thinking | D37: Example | E37: Edge cases | F37: Notes | G37: Open Q | H37: Origin | I37: Status
A38: OB-01 | B38: Verbosity | C38: Normal by default; 'verbose' shows AI captains' events elsewhere in the galaxy. | H38: Claude | I38: Proposed
A39: OB-02 | B39: History | C39: 500 lines; grouped by phase within a turn. | G39: Q-31 | H39: Claude | I39: Proposed
A40: OB-03 | B40: Styling | C40: Colour per severity; same palette as T2 / T4. | H40: Chat A8 | I40: Agreed
A41: OB-04 | B41: Order within a turn | C41: Grouped by phase (movement → hazards → combat → trade → upkeep → reputation). | G41: Q-01 | H41: Ans Q-01 | I41: Proposed

Sheet 5b T4 Status
A1: 5b · T4 Status terminal
A2: The permanent status panel agreed in Q-25
A3: =HYPERLINK("#'0 Index'!A1","↩ Index") -> ↩ Index
A5: Purpose | C5: Always-visible state so T3 can stay a pure log: captain, active ship, fleet, cargo, supplies. | I5: Ans Q-25
A6: Process / module | C6: TBD — e.g. mos/terminals/status.py | I6: Template
A7: Subscribes | C7: turn.resolved | I7: 2 Architecture
A8: Publishes | C8: nothing (display only) | I8: Claude · Proposed
A9: Render library | C9: Rich panels / tables, colour-coded bars | I9: Chat A8
A11: Panels
A12: ID | B12: Panel | C12: Shows | D12: Updates when | E12: Position / size | F12: Notes | G12: Open Q | H12: Origin | I12: Status
A13: PNL-01 | B13: Captain | C13: name, gold, silver, fear (0–100 bar), respect (0–100 bar), eligibility for the ultimate item | D13: turn.resolved | E13: top | G13: Q-15 | H13: Ans Q-15, Q-25 | I13: Agreed
A14: PNL-02 | B14: Active ship | C14: name, class, torpedoes (count), phasers (0–10), shields current / max, engine (0–10), warp core (0–10), position | D14: turn.resolved | E14: middle | G14: Q-12 | H14: Ans Q-25; Claude | I14: Proposed
A15: PNL-03 | B15: Supplies | C15: food, water (turns remaining), colour-coded warning, mutiny countdown when at 0 | D15: turn.resolved | E15: middle | G15: Q-19 | H15: Ans Q-19; Chat A11 | I15: Proposed
A16: PNL-04 | B16: Cargo | C16: elements & compounds held, special items | D16: turn.resolved | E16: lower | H16: Implied r83 | I16: Proposed
A17: PNL-05 | B17: Fleet | C17: every owned ship: name, location, shields, orders queued | D17: turn.resolved | E17: bottom | G17: Q-13 | H17: Ans Q-13 | I17: Proposed
A18: PNL-06 | B18: Hazard / battle | C18: current pull, countdown, enemies in range | D18: turn.resolved | E18: side | F18: Only when relevant | G18: Q-02, Q-12 | H18: Claude | I18: Proposed

Sheet 6 World Grids
A1: 6 · World grids
A2: Universe → Galaxy → Sector, sparse storage, seeded generation
A3: =HYPERLINK("#'0 Index'!A1","↩ Index") -> ↩ Index
A5: Grid hierarchy
A6: ID | B6: Level | C6: Is a grid of | D6: Each cell holds | E6: Size (M × N) | F6: Open Q | G6: Origin | H6: Status
A7: WG-00 | B7: GeneralGrid | C7: — (base class) | D7: Sparse: a dict keyed by (x, y) → cell contents; empty = Void. Bounds M × N are properties. | E7: n/a | F7: Q-04 | G7: BP r30–32; Ans Q-04 | H7: Agreed
A8: WG-01 | B8: Universe | C8: Galaxies | D8: A Galaxy or Void. | E8: 8 × 8 (config) | F8: Q-05 | G8: BP r34–36; Claude | H8: Proposed
A9: WG-02 | B9: Galaxy | C9: Sectors | D9: A Sector or Void. | E9: 16 × 16 (config) | F9: Q-05 | G9: BP r38–40; Claude | H9: Proposed
A10: WG-03 | B10: Sector | C10: Cells | D10: At most one terrain object (star, black hole, neutron star, planet) per cell; any number of items and ships. | E10: 24 × 24 (config) | F10: Q-06 | G10: BP r42–44; Ans Q-06 | H10: Agreed
A12: Generation rules
A13: ID | B13: Rule | C13: Statement | D13: Notes | E13: Config key | F13: Open Q | G13: Origin | H13: Status
A14: SP-01 | B14: Seed | C14: Everything is generated from one seed; the same seed gives the same universe. | D14: Wormhole pairs fixed at seeding. | E14: [world] seed | F14: Q-08 | G14: Ans Q-08, Q-11 | H14: Agreed
A15: SP-02 | B15: Star systems | C15: One star per cell; binary / triple systems are stars in adjacent cells. | E15: [world] multi_star_pct | F15: Q-06 | G15: Ans Q-06 | H15: Agreed
A16: SP-03 | B16: Item density | C16: About 10 special items and 100 normal items per galaxy. | E16: [world] special_items_per_galaxy = 10, normal_items_per_galaxy = 100 | F16: Q-07 | G16: Ans Q-07 | H16: Agreed
A17: SP-04 | B17: Planets | C17: Planets sit in a cell adjacent to a star; 0–3 per system. | E17: [world] planets_per_system_max = 3 | G17: Claude | H17: Proposed
A18: SP-05 | B18: Starting position | C18: Player starts in a sector with a planet and no black hole or neutron star. | E18: [world] safe_start = true | F18: Q-08 | G18: Claude | H18: Proposed
A19: SP-06 | B19: AI captains | C19: 3 AI captains per galaxy, placed in random safe sectors. | E19: [world] ai_captains_per_galaxy = 3 | F19: Q-13 | G19: Claude | H19: Proposed
A20: SP-07 | B20: Sector density | C20: Per sector: 0–3 stars, 0–1 black hole or neutron star (never with the player's start), items per SP-03. | E20: [world] * | G20: Claude | H20: Proposed
A21: SP-08 | B21: Ultimate item | C21: Placed at eligibility time in a sector at least half the universe diameter from the captain, guarded by ships. | E21: [endgame] guard_ships = 4 | F21: Q-15 | G21: Ans Q-15 | H21: Agreed

Sheet 7 Stellar
A1: 7 · Stellar objects
A2: Types, attributes, and the energy → temperature → colour chain with a live calculator
A3: =HYPERLINK("#'0 Index'!A1","↩ Index") -> ↩ Index
A5: Types
A6: ID | B6: Type | C6: Attributes | D6: Notes | E6: Config key | F6: Open Q | G6: Origin | H6: Status
A7: ST-01 | B7: Star | C7: radius, base_energy, mass | D7: Pull and shield drain in its own cell only. Fatal if the ship stays. | G7: BP r49, r51; Ans Q-02 | H7: Agreed
A8: ST-02 | B8: Neutron star | C8: mass (lower than a black hole), radius | D8: Like a black hole but weaker pull: pulls across the sector; fatal if pulled in; no wormhole; no shield drain. | E8: [stellar] neutron_mass | F8: Q-09 | G8: Ans Q-09; Claude | H8: Proposed
A9: ST-03 | B9: Black hole | C9: mass (very high), radius, wormhole (bool) | D9: Pulls across the whole sector; a ship may lack the engine power to escape (8 Hazards calculator). | E9: [stellar] blackhole_mass | G9: BP r60–62; Ans Q-02 | H9: Agreed
A10: ST-04 | B10: Wormhole | C10: Black hole with a fixed partner (set at seeding) | D10: Exit can be in the same or another galaxy; the ship survives the crossing; pulled in again if it stays. | F10: Q-11 | G10: Ans Q-11 | H10: Agreed
A12: Derived quantities
A13: ID | B13: Quantity | C13: Formula | D13: Notes | E13: Config key | F13: Open Q | G13: Origin | H13: Status
A14: DQ-01 | B14: Volume | C14: volume = 4/3 · π · radius³ | F14: Q-10 | G14: Ans Q-10 | H14: Agreed
A15: DQ-02 | B15: Energy | C15: energy = base_energy × volume | F15: Q-10 | G15: BP r57; Ans Q-10 | H15: Agreed
A16: DQ-03 | B16: Temperature | C16: temperature = temp_scale × energy^0.25 | D16: Stefan–Boltzmann flavour; temp_scale = 2 700 gives a Sun-like star ≈ 5 800 K. | E16: [stellar] temp_scale = 2700 | F16: Q-10 | G16: Claude | H16: Proposed
A17: DQ-04 | B17: Colour | C17: colour = lookup(temperature, colour thresholds) | D17: Real stellar sequence: red → orange → yellow → yellow-white → white → blue-white → blue. | E17: [stellar] colour_thresholds | F17: Q-10 | G17: Claude | H17: Proposed
A18: DQ-05 | B18: Pull | C18: pull = k_g × mass / (1 + distance)^falloff (star: same cell only, distance = 0) | D18: Nets against impulse and warp speed (8 Hazards). | E18: [hazards] k_g = 1.0, falloff = 1.5 | F18: Q-02 | G18: Ans Q-02; Claude | H18: Proposed
A21: Star energy buckets
A22: ID | B22: Bucket | C22: Energy range | D22: Example | E22: Config key | F22: Open Q | G22: Origin | H22: Status
A23: EB-01 | B23: Low | C23: energy < 5 | D23: Dying star — radius 0.3, base 2 → energy ≈ 0.2, ≈ 1 900 K, red | E23: [stellar] energy_low_max = 5 | F23: Q-10 | G23: Claude | H23: Proposed
A24: EB-02 | B24: Medium | C24: 5 ≤ energy < 100 | D24: Sun-like — radius 1, base 5 → energy ≈ 21, ≈ 5 800 K, yellow | E24: [stellar] energy_medium_max = 100 | F24: Q-10 | G24: Claude | H24: Proposed
A25: EB-03 | B25: High | C25: energy ≥ 100 | D25: Giant — radius 3, base 8 → energy ≈ 905, ≈ 14 800 K, blue-white | E25: — | F25: Q-10 | G25: Claude | H25: Proposed
A28: Calculator — change the yellow inputs and the rows below recompute
A29: Inputs are placeholders; tune in playtest.
A30: temp_scale | B30: 2700 | C30: [stellar] temp_scale
A31: energy_low_max | B31: 5 | C31: [stellar] energy_low_max
A32: energy_medium_max | B32: 100 | C32: [stellar] energy_medium_max
A34: Colour thresholds (K)
A35: 0 | B35: red
A36: 3700 | B36: orange
A37: 5200 | B37: yellow
